File: data/rheometry/monomer_2equiv.txt
Shear rate	Viscosity
1/s	[mPaÂ·s]
0.00215385	936.334
0.00464167	400.861
0.00999256	228.53
0.0215414	98.0171
0.0464267	54.8123
0.0999991	26.1202
0.215442	22.8756
0.464146	19.5843
0.999991	15.6834
2.15439	14.6245
4.64147	14.7178
9.99971	14.7606
100	14.7512